Workbook

Sheet About
L1: Created on: | M1: 12 Apr 25 09:09 UTC
L2: Jira Site: | M2: https://tataunistore.atlassian.net
L3: Jira Query: | M3: project = "UCW" AND "agency[dropdown]" = Netscribes ORDER BY created DESC

Sheet Your Jira Issues
A1: Key | B1: Summary | C1: Status | D1: Priority | E1: Assignee | F1: Reporter | G1: Created | H1: Updated | I1: Total SKU Count | J1: Listing Type - Sorted | K1: Listing Type | L1: L1 for UCW | M1: Closed SKU Count | N1: Listed Option Count | O1: Total Option Count | P1: Brand Name | Q1: Platform. | R1: Comment | S1: TAT (Days) | T1: Brand To resolve | U1: Comment2
A2: UCW-30466 | B2: Necklace category file for Listing in TATA CLIQ | C2: CLOSED | D2: Medium | E2: Sushma Ram | F2: Sushma Ram | G2: 46143.042 | H2: 46147.714 | I2: 4 | J2: E2E | K2: E2E | L2: Jewellery | M2: 4 | N2: 4 | O2: 4 | P2: Saraf RS Jewellery | Q2: Mall | R2: PFA the Summary & Post-Uploaded sheet[^UCW-30466 Post Upload Status_V.2 (1).xlsx] [^Summary.zip] ;[^UCW-30466_LID.xlsx] Hi [@Rajiv Saraf|mailto:hbtraders1973@gmail.com], Please find attached the sheet, where 0 options have been listed. Kindly update the price and inventory, and share the summary once completed. {adf:display=block} {"type":"table","attrs":{"isNumberColumnEnabled":false,"layout":"center","localId":"d5a19c3b-6809-4370-90ac-f019e899de0c"},"content":[{"type":"tableRow","content":[{"type":"tableCell","attrs":{"background":"#44b3e1"},"content":[{"type":"paragraph","content":[{"type":"text","text":"Ticket ID","marks":[{"type":"strong"}]}]}]},{"type":"tableCell","attrs":{"colspan":2,"background":"#44b3e1"},"content":[{"type":"paragraph","content":[{"type":"text","text":"UCW-30466","marks":[{"type":"strong"}]}]}]}]},{"type":"tableRow","content":[{"type":"tableCell","attrs":{"background":"#44b3e1"},"content":[{"type":"paragraph","content":[{"type":"text","text":"Brand Name","marks":[{"type":"strong"}]}]}]},{"type":"tableCell","attrs":{"colspan":2,"background":"#44b3e1"},"content":[{"type":"paragraph","content":[{"type":"text","text":"Saraf RS Jewellery","marks":[{"type":"strong"}]}]}]}]},{"type":"tableRow","content":[{"type":"tableCell","attrs":{"background":"#44b3e1"},"content":[{"type":"paragraph","content":[{"type":"text","text":"Platform","marks":[{"type":"strong"}]}]}]},{"type":"tableCell","attrs":{"colspan":2,"background":"#44b3e1"},"content":[{"type":"paragraph","content":[{"type":"text","text":"Mall","marks":[{"type":"strong"}]}]}]}]},{"type":"tableRow","content":[{"type":"tableCell","attrs":{"background":"#ace5fe"},"content":[{"type":"paragraph","content":[{"type":"text","text":"Particulars","marks":[{"type":"strong"}]}]}]},{"type":"tableCell","attrs":{"background":"#ace5fe"},"content":[{"type":"paragraph","content":[{"type":"text","text":"SKU Count","marks":[{"type":"strong"}]}]}]},{"type":"tableCell","attrs":{"background":"#ace5fe"},"content":[{"type":"paragraph","content":[{"type":"text","text":"Option Count","marks":[{"type":"strong"}]}]}]}]},{"type":"tableRow","content":[{"type":"tableCell","attrs":{"background":"white"},"content":[{"type":"paragraph","content":[{"type":"text","text":"Received"}]}]},{"type":"tableCell","attrs":{"background":"white"},"content":[{"type":"paragraph","content":[{"type":"text","text":"4"}]}]},{"type":"tableCell","attrs":{"background":"white"},"content":[{"type":"paragraph","content":[{"type":"text","text":"4"}]}]}]},{"type":"tableRow","content":[{"type":"tableCell","attrs":{"background":"white"},"content":[{"type":"paragraph","content":[{"type":"text","text":"Uploaded"}]}]},{"type":"tableCell","attrs":{"background":"white"},"content":[{"type":"paragraph","content":[{"type":"text","text":"4"}]}]},{"type":"tableCell","attrs":{"background":"white"},"content":[{"type":"paragraph","content":[{"type":"text","text":"0"}]}]}]},{"type":"tableRow","content":[{"type":"tableCell","attrs":{"background":"white"},"content":[{"type":"paragraph","content":[{"type":"text","text":"Not Uploaded"}]}]},{"type":"tableCell","attrs":{"background":"white"},"content":[{"type":"paragraph","content":[{"type":"text","text":"0"}]}]},{"type":"tableCell","attrs":{"background":"white"},"content":[{"type":"paragraph","content":[{"type":"text","text":"4"}]}]}]},{"type":"tableRow","content":[{"type":"tableCell","attrs":{"background":"white"},"content":[{"type":"paragraph","content":[{"type":"text","text":"LIDs Shared"}]}]},{"type":"tableCell","attrs":{"background":"white"},"content":[{"type":"paragraph","content":[{"type":"text","text":"4"}]}]},{"type":"tableCell","attrs":{"background":"white"},"content":[{"type":"paragraph","content":[{"type":"text","text":"0"}]}]}]},{"type":"tableRow","content":[{"type":"tableCell","attrs":{"background":"white"},"content":[{"type":"paragraph","content":[{"type":"text","text":"LIDs Stuck in the System"}]}]},{"type":"tableCell","attrs":{"background":"white"},"content":[{"type":"paragraph","content":[{"type":"text","text":"0"}]}]},{"type":"tableCell","attrs":{"background":"white"},"content":[{"type":"paragraph","content":[{"type":"text","text":"0"}]}]}]}]} {adf} Regards, Team Netscribes | S2: =IF(OR(G2="",H2=""),"",ROUND(H2-G2,2)) -> 4.67
A3: UCW-30472 | B3: ENRICH_Request for Product Image Update | C3: CLOSED Due to Inactive/Insufficient Information | D3: Medium | E3: netscribes | F3: Sushma Ram | G3: 46143.141 | H3: 46155.545 | I3: 1 | J3: Ad-hoc | K3: Retrigger Image | L3: Beauty & Grooming | M3: 0 | N3: 0 | O3: 1 | P3: Signaxo | Q3: Mall | R3: Duplicate worked on UCW-30480 | S3: =IF(OR(G3="",H3=""),"",ROUND(H3-G3,2)) -> 12.4
A4: UCW-30480 | B4: Enrich_Request for Product Image Update | C4: CLOSED | D4: Medium | E4: Chirag Dubal | F4: Simi Raichel Zachariah | G4: 46143.499 | H4: 46158.65 | I4: 1 | J4: Ad-hoc | K4: Retrigger Image | L4: Beauty & Grooming | M4: 1 | N4: 1 | O4: 1 | P4: signaxo | Q4: Mall | R4: The changes have been successfully updated and are now reflecting on both the Marketplace and Luxury platforms. Please find the attached screenshot for your reference. !image-20260516-100619.png|width=532,alt="image-20260516-100619.png"! !image-20260516-100628.png|width=517,alt="image-20260516-100628.png"! Regards, Team Netscribes | S4: =IF(OR(G4="",H4=""),"",ROUND(H4-G4,2)) -> 15.15
A5: UCW-30488 | B5: New Listings For Gold (21/04/2026) | C5: CLOSED | D5: Medium | E5: netscribes | F5: Sushma Ram | G5: 46143.585 | H5: 46155.713 | I5: 310 | J5: E2E | K5: E2E | L5: Jewellery | M5: 310 | N5: 310 | O5: 310 | P5: Joyalukkas | Q5: Mall | R5: PFA the Summary & Post-uploaded sheet[^UCW-30488 Post Upload Status_V.2 (1).xlsx] [^Summary.zip] ;[^UCW-30488_LID.xlsx] Hi [@Haripriya Nagaraj|mailto:haripriyanr@joyalukkas.com], Please find attached the sheet, where 310 options have been listed. Kindly update the price and inventory, and share the summary once completed. {adf:display=block} {"type":"table","attrs":{"isNumberColumnEnabled":false,"layout":"center","localId":"6a66edf7-d329-4239-87f3-34b68a6ec4a3"},"content":[{"type":"tableRow","content":[{"type":"tableCell","attrs":{"background":"#44b3e1"},"content":[{"type":"paragraph","content":[{"type":"text","text":"Ticket ID","marks":[{"type":"strong"}]}]}]},{"type":"tableCell","attrs":{"colspan":2,"background":"#44b3e1"},"content":[{"type":"paragraph","content":[{"type":"text","text":"UCW-30488","marks":[{"type":"strong"}]}]}]}]},{"type":"tableRow","content":[{"type":"tableCell","attrs":{"background":"#44b3e1"},"content":[{"type":"paragraph","content":[{"type":"text","text":"Brand Name","marks":[{"type":"strong"}]}]}]},{"type":"tableCell","attrs":{"colspan":2,"background":"#44b3e1"},"content":[{"type":"paragraph","content":[{"type":"text","text":"Joyalukkas","marks":[{"type":"strong"}]}]}]}]},{"type":"tableRow","content":[{"type":"tableCell","attrs":{"background":"#44b3e1"},"content":[{"type":"paragraph","content":[{"type":"text","text":"Platform","marks":[{"type":"strong"}]}]}]},{"type":"tableCell","attrs":{"colspan":2,"background":"#44b3e1"},"content":[{"type":"paragraph","content":[{"type":"text","text":"Mall","marks":[{"type":"strong"}]}]}]}]},{"type":"tableRow","content":[{"type":"tableCell","attrs":{"background":"#ace5fe"},"content":[{"type":"paragraph","content":[{"type":"text","text":"Particulars","marks":[{"type":"strong"}]}]}]},{"type":"tableCell","attrs":{"background":"#ace5fe"},"content":[{"type":"paragraph","content":[{"type":"text","text":"SKU Count","marks":[{"type":"strong"}]}]}]},{"type":"tableCell","attrs":{"background":"#ace5fe"},"content":[{"type":"paragraph","content":[{"type":"text","text":"Option Count","marks":[{"type":"strong"}]}]}]}]},{"type":"tableRow","content":[{"type":"tableCell","attrs":{"background":"white"},"content":[{"type":"paragraph","content":[{"type":"text","text":"Received"}]}]},{"type":"tableCell","attrs":{"background":"white"},"content":[{"type":"paragraph","content":[{"type":"text","text":"310"}]}]},{"type":"tableCell","attrs":{"background":"white"},"content":[{"type":"paragraph","content":[{"type":"text","text":"310"}]}]}]},{"type":"tableRow","content":[{"type":"tableCell","attrs":{"background":"white"},"content":[{"type":"paragraph","content":[{"type":"text","text":"Uploaded"}]}]},{"type":"tableCell","attrs":{"background":"white"},"content":[{"type":"paragraph","content":[{"type":"text","text":"310"}]}]},{"type":"tableCell","attrs":{"background":"white"},"content":[{"type":"paragraph","content":[{"type":"text","text":"310"}]}]}]},{"type":"tableRow","content":[{"type":"tableCell","attrs":{"background":"white"},"content":[{"type":"paragraph","content":[{"type":"text","text":"Not Uploaded"}]}]},{"type":"tableCell","attrs":{"background":"white"},"content":[{"type":"paragraph","content":[{"type":"text","text":"0"}]}]},{"type":"tableCell","attrs":{"background":"white"},"content":[{"type":"paragraph","content":[{"type":"text","text":"0"}]}]}]},{"type":"tableRow","content":[{"type":"tableCell","attrs":{"background":"white"},"content":[{"type":"paragraph","content":[{"type":"text","text":"LIDs Shared"}]}]},{"type":"tableCell","attrs":{"background":"white"},"content":[{"type":"paragraph","content":[{"type":"text","text":"310"}]}]},{"type":"tableCell","attrs":{"background":"white"},"content":[{"type":"paragraph","content":[{"type":"text","text":"310"}]}]}]},{"type":"tableRow","content":[{"type":"tableCell","attrs":{"background":"white"},"content":[{"type":"paragraph","content":[{"type":"text","text":"LIDs Stuck in the System"}]}]},{"type":"tableCell","attrs":{"background":"white"},"content":[{"type":"paragraph","content":[{"type":"text","text":"0"}]}]},{"type":"tableCell","attrs":{"background":"white"},"content":[{"type":"paragraph","content":[{"type":"text","text":"0"}]}]}]}]} {adf} Regards, Team Netscribes | S5: =IF(OR(G5="",H5=""),"",ROUND(H5-G5,2)) -> 12.13
A6: UCW-30497 | B6: Brand Name: SaintG, Category: Footwear, Seller Code: 128447/128537, Listing Type: New Listing, No of SKus:468 No of Options:78 Date:15.04.2026 | C6: CLOSED | D6: Medium | E6: netscribes | F6: Sushma Ram | G6: 46143.658 | H6: 46155.713 | I6: 468 | J6: E2E | K6: E2E+Dual Listing | L6: Footwear | M6: 36 | N6: 6 | O6: 78 | P6: Saint G | Q6: Mall;Luxury | R6: We have successfully uploaded this batch. Please find the attached summary sheet and summary report.[^Summary.zip] [^Post Upload Status_V.2 (1).xlsx] ;[^UCW-30497_LID.xlsx] Hi [@Sagar|mailto:sagar@saintgshoes.com], Please find attached the sheet, where 6 options on Mall and 6 options on Luxury have been listed. Kindly update the price and inventory, and share the summary once completed. {adf:display=block} {"type":"table","attrs":{"isNumberColumnEnabled":false,"layout":"center","localId":"23970458-106d-4aff-b4bf-ffaa8c29047f"},"content":[{"type":"tableRow","content":[{"type":"tableCell","attrs":{"background":"#4d93d9"},"content":[{"type":"paragraph","content":[{"type":"text","text":"Ticket ID","marks":[{"type":"strong"}]}]}]},{"type":"tableCell","attrs":{"colspan":4,"background":"#4d93d9"},"content":[{"type":"paragraph","content":[{"type":"text","text":"UCW-30497","marks":[{"type":"strong"}]}]}]}]},{"type":"tableRow","content":[{"type":"tableCell","attrs":{"background":"#4d93d9"},"content":[{"type":"paragraph","content":[{"type":"text","text":"Brand Name","marks":[{"type":"strong"}]}]}]},{"type":"tableCell","attrs":{"colspan":4,"background":"#4d93d9"},"content":[{"type":"paragraph","content":[{"type":"text","text":"Saint G","marks":[{"type":"strong"}]}]}]}]},{"type":"tableRow","content":[{"type":"tableCell","attrs":{"background":"#ace5fe"},"content":[{"type":"paragraph","content":[{"type":"text","text":"Platform","marks":[{"type":"strong"}]}]}]},{"type":"tableCell","attrs":{"colspan":2,"background":"#ace5fe"},"content":[{"type":"paragraph","content":[{"type":"text","text":"Mall","marks":[{"type":"strong"}]}]}]},{"type":"tableCell","attrs":{"colspan":2,"background":"#ace5fe"},"content":[{"type":"paragraph","content":[{"type":"text","text":"Luxury","marks":[{"type":"strong"}]}]}]}]},{"type":"tableRow","content":[{"type":"tableCell","attrs":{"background":"#ace5fe"},"content":[{"type":"paragraph","content":[{"type":"text","text":"Particulars","marks":[{"type":"strong"}]}]}]},{"type":"tableCell","attrs":{"background":"#ace5fe"},"content":[{"type":"paragraph","content":[{"type":"text","text":"SKU Count","marks":[{"type":"strong"}]}]}]},{"type":"tableCell","attrs":{"background":"#ace5fe"},"content":[{"type":"paragraph","content":[{"type":"text","text":"Option Count","marks":[{"type":"strong"}]}]}]},{"type":"tableCell","attrs":{"background":"#ace5fe"},"content":[{"type":"paragraph","content":[{"type":"text","text":"SKU Count","marks":[{"type":"strong"}]}]}]},{"type":"tableCell","attrs":{"background":"#ace5fe"},"content":[{"type":"paragraph","content":[{"type":"text","text":"Option Count","marks":[{"type":"strong"}]}]}]}]},{"type":"tableRow","content":[{"type":"tableCell","attrs":{"background":"white"},"content":[{"type":"paragraph","content":[{"type":"text","text":"Received"}]}]},{"type":"tableCell","attrs":{"background":"white"},"content":[{"type":"paragraph","content":[{"type":"text","text":"468"}]}]},{"type":"tableCell","attrs":{"background":"white"},"content":[{"type":"paragraph","content":[{"type":"text","text":"78"}]}]},{"type":"tableCell","attrs":{"background":"white"},"content":[{"type":"paragraph","content":[{"type":"text","text":"468"}]}]},{"type":"tableCell","attrs":{"background":"white"},"content":[{"type":"paragraph","content":[{"type":"text","text":"78"}]}]}]},{"type":"tableRow","content":[{"type":"tableCell","attrs":{"background":"white"},"content":[{"type":"paragraph","content":[{"type":"text","text":"Uploaded"}]}]},{"type":"tableCell","attrs":{"background":"white"},"content":[{"type":"paragraph","content":[{"type":"text","text":"36"}]}]},{"type":"tableCell","attrs":{"background":"white"},"content":[{"type":"paragraph","content":[{"type":"text","text":"6"}]}]},{"type":"tableCell","attrs":{"background":"white"},"content":[{"type":"paragraph","content":[{"type":"text","text":"36"}]}]},{"type":"tableCell","attrs":{"background":"white"},"content":[{"type":"paragraph","content":[{"type":"text","text":"6"}]}]}]},{"type":"tableRow","content":[{"type":"tableCell","attrs":{"background":"white"},"content":[{"type":"paragraph","content":[{"type":"text","text":"SKUs Not Uploaded"}]}]},{"type":"tableCell","attrs":{"background":"white"},"content":[{"type":"paragraph","content":[{"type":"text","text":"432"}]}]},{"type":"tableCell","attrs":{"background":"white"},"content":[{"type":"paragraph","content":[{"type":"text","text":"72"}]}]},{"type":"tableCell","attrs":{"background":"white"},"content":[{"type":"paragraph","content":[{"type":"text","text":"432"}]}]},{"type":"tableCell","attrs":{"background":"white"},"content":[{"type":"paragraph","content":[{"type":"text","text":"72"}]}]}]},{"type":"tableRow","content":[{"type":"tableCell","attrs":{"background":"white"},"content":[{"type":"paragraph","content":[{"type":"text","text":"LIDs Shared"}]}]},{"type":"tableCell","attrs":{"background":"white"},"content":[{"type":"paragraph","content":[{"type":"text","text":"36"}]}]},{"type":"tableCell","attrs":{"background":"white"},"content":[{"type":"paragraph","content":[{"type":"text","text":"6"}]}]},{"type":"tableCell","attrs":{"background":"white"},"content":[{"type":"paragraph","content":[{"type":"text","text":"36"}]}]},{"type":"tableCell","attrs":{"background":"white"},"content":[{"type":"paragraph","content":[{"type":"text","text":"6"}]}]}]},{"type":"tableRow","content":[{"type":"tableCell","attrs":{"background":"white"},"content":[{"type":"paragraph","content":[{"type":"text","text":"LIDs Stuck in the System"}]}]},{"type":"tableCell","attrs":{"background":"white"},"content":[{"type":"paragraph","content":[{"type":"text","text":"0"}]}]},{"type":"tableCell","attrs":{"background":"white"},"content":[{"type":"paragraph","content":[{"type":"text","text":"0"}]}]},{"type":"tableCell","attrs":{"background":"white"},"content":[{"type":"paragraph","content":[{"type":"text","text":"0"}]}]},{"type":"tableCell","attrs":{"background":"white"},"content":[{"type":"paragraph","content":[{"type":"text","text":"0"}]}]}]}]} {adf} Regards, Team Netscribes | S6: =IF(OR(G6="",H6=""),"",ROUND(H6-G6,2)) -> 12.06
A7: UCW-30523 | B7: TQ | Brand: Converse | Catalog Listing | SP26 Elevation Style. | C7: CLOSED | D7: Medium | E7: Chirag Dubal | F7: Shloka Chakre | G7: 46143.81 | H7: 46147.78 | I7: 59 | J7: E2E | K7: E2E+Dual Listing | L7: Footwear | M7: 59 | N7: 11 | O7: 11 | P7: Converse | Q7: Mall;Luxury | R7: We have successfully uploaded this batch. Please find the attached summary sheet and summary report.[^Post Upload Status_V.2 (1).xlsx] [^Summary.zip] ;[^UCW-30523_LID.xlsx] Hi [@Amit Kumar|mailto:amit@bhaane.com], Please find attached the sheet, where 9 options have been listed on Luxury and 11 options have been listed on Marketplace platform. Kindly update the price and inventory, and share the summary once completed. {adf:display=block} {"type":"table","attrs":{"isNumberColumnEnabled":false,"layout":"center","localId":"53f03b1a-a495-44eb-b6f6-c3f00175a829"},"content":[{"type":"tableRow","content":[{"type":"tableCell","attrs":{"background":"#4d93d9"},"content":[{"type":"paragraph","content":[{"type":"text","text":"Ticket ID","marks":[{"type":"strong"}]}]}]},{"type":"tableCell","attrs":{"colspan":4,"background":"#4d93d9"},"content":[{"type":"paragraph","content":[{"type":"text","text":"UCW-30523","marks":[{"type":"strong"}]}]}]}]},{"type":"tableRow","content":[{"type":"tableCell","attrs":{"background":"#4d93d9"},"content":[{"type":"paragraph","content":[{"type":"text","text":"Brand Name","marks":[{"type":"strong"}]}]}]},{"type":"tableCell","attrs":{"colspan":4,"background":"#4d93d9"},"content":[{"type":"paragraph","content":[{"type":"text","text":"Converse","marks":[{"type":"strong"}]}]}]}]},{"type":"tableRow","content":[{"type":"tableCell","attrs":{"background":"#ace5fe"},"content":[{"type":"paragraph","content":[{"type":"text","text":"Platform","marks":[{"type":"strong"}]}]}]},{"type":"tableCell","attrs":{"colspan":2,"background":"#ace5fe"},"content":[{"type":"paragraph","content":[{"type":"text","text":"Luxury","marks":[{"type":"strong"}]}]}]},{"type":"tableCell","attrs":{"colspan":2,"background":"#ace5fe"},"content":[{"type":"paragraph","content":[{"type":"text","text":"Marketplace","marks":[{"type":"strong"}]}]}]}]},{"type":"tableRow","content":[{"type":"tableCell","attrs":{"background":"#ace5fe"},"content":[{"type":"paragraph","content":[{"type":"text","text":"Particulars","marks":[{"type":"strong"}]}]}]},{"type":"tableCell","attrs":{"background":"#ace5fe"},"content":[{"type":"paragraph","content":[{"type":"text","text":"SKU Count","marks":[{"type":"strong"}]}]}]},{"type":"tableCell","attrs":{"background":"#ace5fe"},"content":[{"type":"paragraph","content":[{"type":"text","text":"Option Count","marks":[{"type":"strong"}]}]}]},{"type":"tableCell","attrs":{"background":"#ace5fe"},"content":[{"type":"paragraph","content":[{"type":"text","text":"SKU Count","marks":[{"type":"strong"}]}]}]},{"type":"tableCell","attrs":{"background":"#ace5fe"},"content":[{"type":"paragraph","content":[{"type":"text","text":"Option Count","marks":[{"type":"strong"}]}]}]}]},{"type":"tableRow","content":[{"type":"tableCell","attrs":{"background":"white"},"content":[{"type":"paragraph","content":[{"type":"text","text":"Received"}]}]},{"type":"tableCell","attrs":{"background":"white"},"content":[{"type":"paragraph","content":[{"type":"text","text":"59"}]}]},{"type":"tableCell","attrs":{"background":"white"},"content":[{"type":"paragraph","content":[{"type":"text","text":"11"}]}]},{"type":"tableCell","attrs":{"background":"white"},"content":[{"type":"paragraph","content":[{"type":"text","text":"59"}]}]},{"type":"tableCell","attrs":{"background":"white"},"content":[{"type":"paragraph","content":[{"type":"text","text":"11"}]}]}]},{"type":"tableRow","content":[{"type":"tableCell","attrs":{"background":"white"},"content":[{"type":"paragraph","content":[{"type":"text","text":"Uploaded"}]}]},{"type":"tableCell","attrs":{"background":"white"},"content":[{"type":"paragraph","content":[{"type":"text","text":"49"}]}]},{"type":"tableCell","attrs":{"background":"white"},"content":[{"type":"paragraph","content":[{"type":"text","text":"9"}]}]},{"type":"tableCell","attrs":{"background":"white"},"content":[{"type":"paragraph","content":[{"type":"text","text":"59"}]}]},{"type":"tableCell","attrs":{"background":"white"},"content":[{"type":"paragraph","content":[{"type":"text","text":"11"}]}]}]},{"type":"tableRow","content":[{"type":"tableCell","attrs":{"background":"white"},"content":[{"type":"paragraph","content":[{"type":"text","text":"SKUs Not Uploaded"}]}]},{"type":"tableCell","attrs":{"background":"white"},"content":[{"type":"paragraph","content":[{"type":"text","text":"10"}]}]},{"type":"tableCell","attrs":{"background":"white"},"content":[{"type":"paragraph","content":[{"type":"text","text":"2"}]}]},{"type":"tableCell","attrs":{"background":"white"},"content":[{"type":"paragraph","content":[{"type":"text","text":"0"}]}]},{"type":"tableCell","attrs":{"background":"white"},"content":[{"type":"paragraph","content":[{"type":"text","text":"0"}]}]}]},{"type":"tableRow","content":[{"type":"tableCell","attrs":{"background":"white"},"content":[{"type":"paragraph","content":[{"type":"text","text":"LIDs Shared"}]}]},{"type":"tableCell","attrs":{"background":"white"},"content":[{"type":"paragraph","content":[{"type":"text","text":"49"}]}]},{"type":"tableCell","attrs":{"background":"white"},"content":[{"type":"paragraph","content":[{"type":"text","text":"9"}]}]},{"type":"tableCell","attrs":{"background":"white"},"content":[{"type":"paragraph","content":[{"type":"text","text":"59"}]}]},{"type":"tableCell","attrs":{"background":"white"},"content":[{"type":"paragraph","content":[{"type":"text","text":"11"}]}]}]},{"type":"tableRow","content":[{"type":"tableCell","attrs":{"background":"white"},"content":[{"type":"paragraph","content":[{"type":"text","text":"LIDs Stuck in the System"}]}]},{"type":"tableCell","attrs":{"background":"white"},"content":[{"type":"paragraph","content":[{"type":"text","text":"0"}]}]},{"type":"tableCell","attrs":{"background":"white"},"content":[{"type":"paragraph","content":[{"type":"text","text":"0"}]}]},{"type":"tableCell","attrs":{"background":"white"},"content":[{"type":"paragraph","content":[{"type":"text","text":"0"}]}]},{"type":"tableCell","attrs":{"background":"white"},"content":[{"type":"paragraph","content":[{"type":"text","text":"0"}]}]}]}]} {adf} Regards, Team Netscribes | S7: =IF(OR(G7="",H7=""),"",ROUND(H7-G7,2)) -> 3.97
A8: UCW-30530 | B8: Inventory Report : Titan || Tata Cliq | C8: CLOSED | D8: Medium | E8: netscribes | F8: Shraddha Dighe | G8: 46143.865 | H8: 46155.738 | I8: 39 | J8: Ad-hoc | K8: E2E Relisting-SKU change | L8: HOME | M8: 39 | N8: 39 | O8: 39 | P8: Titan | Q8: Mall | S8: =IF(OR(G8="",H8=""),"",ROUND(H8-G8,2)) -> 11.87
A9: UCW-30531 | B9: Libas Apparel 127532 29-04-2026 (NEW CATALOGUE) | C9: CLOSED | D9: Medium | E9: Chirag Dubal | F9: Shraddha Dighe | G9: 46143.899 | H9: 46146.507 | I9: 228 | J9: E2E | K9: E2E | L9: Apparel | M9: 228 | N9: 228 | O9: 228 | P9: Libas | Q9: Mall | R9: PFA the Post Upload Sheet & Summary. [^Post Upload Status_UCW-30531.xlsx] [^Summary.zip] ;[^Post Upload Status_UCW-30531 (2cce4ea3-b227-4d35-a7f5-9c50af3dbd64).xlsx] Please find attached the sheet, where 228 options of Women's Apparel have been listed. Kindly update the price and inventory, and share the summary once completed. {color:#ffffff}__{color} {adf:display=block} {"type":"table","attrs":{"isNumberColumnEnabled":false,"layout":"center","localId":"87860848-2008-47fa-832b-193ecbcbe1e8"},"content":[{"type":"tableRow","content":[{"type":"tableCell","attrs":{"background":"#44b3e1"},"content":[{"type":"paragraph","content":[{"type":"text","text":"Ticket ID","marks":[{"type":"strong"}]}]}]},{"type":"tableCell","attrs":{"colspan":2,"background":"#44b3e1"},"content":[{"type":"paragraph","content":[{"type":"text","text":"UCW-30531","marks":[{"type":"strong"}]}]}]}]},{"type":"tableRow","content":[{"type":"tableCell","attrs":{"background":"#44b3e1"},"content":[{"type":"paragraph","content":[{"type":"text","text":"Brand Name","marks":[{"type":"strong"}]}]}]},{"type":"tableCell","attrs":{"colspan":2,"background":"#44b3e1"},"content":[{"type":"paragraph","content":[{"type":"text","text":"Libas","marks":[{"type":"strong"}]}]}]}]},{"type":"tableRow","content":[{"type":"tableCell","attrs":{"background":"#ace5fe"},"content":[{"type":"paragraph","content":[{"type":"text","text":"Platform","marks":[{"type":"strong"}]}]}]},{"type":"tableCell","attrs":{"colspan":2,"background":"#ace5fe"},"content":[{"type":"paragraph","content":[{"type":"text","text":"Mall","marks":[{"type":"strong"}]}]}]}]},{"type":"tableRow","content":[{"type":"tableCell","attrs":{"background":"#ace5fe"},"content":[{"type":"paragraph","content":[{"type":"text","text":"Particulars","marks":[{"type":"strong"}]}]}]},{"type":"tableCell","attrs":{"background":"#ace5fe"},"content":[{"type":"paragraph","content":[{"type":"text","text":"SKU Count","marks":[{"type":"strong"}]}]}]},{"type":"tableCell","attrs":{"background":"#ace5fe"},"content":[{"type":"paragraph","content":[{"type":"text","text":"Option Count","marks":[{"type":"strong"}]}]}]}]},{"type":"tableRow","content":[{"type":"tableCell","attrs":{"background":"white"},"content":[{"type":"paragraph","content":[{"type":"text","text":"Received"}]}]},{"type":"tableCell","attrs":{},"content":[{"type":"paragraph","content":[{"type":"text","text":"228"}]}]},{"type":"tableCell","attrs":{},"content":[{"type":"paragraph","content":[{"type":"text","text":"228"}]}]}]},{"type":"tableRow","content":[{"type":"tableCell","attrs":{"background":"white"},"content":[{"type":"paragraph","content":[{"type":"text","text":"Uploaded"}]}]},{"type":"tableCell","attrs":{},"content":[{"type":"paragraph","content":[{"type":"text","text":"228"}]}]},{"type":"tableCell","attrs":{},"content":[{"type":"paragraph","content":[{"type":"text","text":"228"}]}]}]},{"type":"tableRow","content":[{"type":"tableCell","attrs":{"background":"white"},"content":[{"type":"paragraph","content":[{"type":"text","text":"LIDs Shared"}]}]},{"type":"tableCell","attrs":{},"content":[{"type":"paragraph","content":[{"type":"text","text":"228"}]}]},{"type":"tableCell","attrs":{},"content":[{"type":"paragraph","content":[{"type":"text","text":"228"}]}]}]},{"type":"tableRow","content":[{"type":"tableCell","attrs":{"background":"white"},"content":[{"type":"paragraph","content":[{"type":"text","text":"LIDs Stuck in the System"}]}]},{"type":"tableCell","attrs":{},"content":[{"type":"paragraph","content":[{"type":"text","text":"0"}]}]},{"type":"tableCell","attrs":{},"content":[{"type":"paragraph","content":[{"type":"text","text":"0"}]}]}]}]} {adf} | S9: =IF(OR(G9="",H9=""),"",ROUND(H9-G9,2)) -> 2.61
A10: UCW-30533 | B10: 22 Pro Listing File ( SS26) | C10: CLOSED | D10: Medium | E10: Chirag Dubal | F10: Shraddha Dighe | G10: 46143.947 | H10: 46155.738 | I10: 107 | J10: E2E | K10: E2E | L10: Apparel | M10: 84 | N10: 17 | O10: 21 | P10: Juniper | Q10: Mall | R10: PFA the Post Upload Sheet & Summary. [^Post Upload Status_UCW-30533.xlsx] [^Summary.zip] ;[^UCW-30533_LID.xlsx] Hi [@chandramohan Juniper|mailto:chandramohan@juniperfashion.com], Please find attached the sheet, where 17 options have been listed. Kindly update the price and inventory, and share the summary once completed. {adf:display=block} {"type":"table","attrs":{"isNumberColumnEnabled":false,"layout":"center","localId":"bf77685b-d7d5-4317-a398-70d1e447105a"},"content":[{"type":"tableRow","content":[{"type":"tableCell","attrs":{"background":"#44b3e1"},"content":[{"type":"paragraph","content":[{"type":"text","text":"Ticket ID","marks":[{"type":"strong"}]}]}]},{"type":"tableCell","attrs":{"colspan":2,"background":"#44b3e1"},"content":[{"type":"paragraph","content":[{"type":"text","text":"UCW-30533","marks":[{"type":"strong"}]}]}]}]},{"type":"tableRow","content":[{"type":"tableCell","attrs":{"background":"#44b3e1"},"content":[{"type":"paragraph","content":[{"type":"text","text":"Brand Name","marks":[{"type":"strong"}]}]}]},{"type":"tableCell","attrs":{"colspan":2,"background":"#44b3e1"},"content":[{"type":"paragraph","content":[{"type":"text","text":"Juniper","marks":[{"type":"strong"}]}]}]}]},{"type":"tableRow","content":[{"type":"tableCell","attrs":{"background":"#44b3e1"},"content":[{"type":"paragraph","content":[{"type":"text","text":"Platform","marks":[{"type":"strong"}]}]}]},{"type":"tableCell","attrs":{"colspan":2,"background":"#44b3e1"},"content":[{"type":"paragraph","content":[{"type":"text","text":"Mall","marks":[{"type":"strong"}]}]}]}]},{"type":"tableRow","content":[{"type":"tableCell","attrs":{"background":"#ace5fe"},"content":[{"type":"paragraph","content":[{"type":"text","text":"Particulars","marks":[{"type":"strong"}]}]}]},{"type":"tableCell","attrs":{"background":"#ace5fe"},"content":[{"type":"paragraph","content":[{"type":"text","text":"SKU Count","marks":[{"type":"strong"}]}]}]},{"type":"tableCell","attrs":{"background":"#ace5fe"},"content":[{"type":"paragraph","content":[{"type":"text","text":"Option Count","marks":[{"type":"strong"}]}]}]}]},{"type":"tableRow","content":[{"type":"tableCell","attrs":{"background":"white"},"content":[{"type":"paragraph","content":[{"type":"text","text":"Received"}]}]},{"type":"tableCell","attrs":{"background":"white"},"content":[{"type":"paragraph","content":[{"type":"text","text":"107"}]}]},{"type":"tableCell","attrs":{"background":"white"},"content":[{"type":"paragraph","content":[{"type":"text","text":"21"}]}]}]},{"type":"tableRow","content":[{"type":"tableCell","attrs":{"background":"white"},"content":[{"type":"paragraph","content":[{"type":"text","text":"Uploaded"}]}]},{"type":"tableCell","attrs":{"background":"white"},"content":[{"type":"paragraph","content":[{"type":"text","text":"84"}]}]},{"type":"tableCell","attrs":{"background":"white"},"content":[{"type":"paragraph","content":[{"type":"text","text":"17"}]}]}]},{"type":"tableRow","content":[{"type":"tableCell","attrs":{"background":"white"},"content":[{"type":"paragraph","content":[{"type":"text","text":"Not Uploaded"}]}]},{"type":"tableCell","attrs":{"background":"white"},"content":[{"type":"paragraph","content":[{"type":"text","text":"23"}]}]},{"type":"tableCell","attrs":{"background":"white"},"content":[{"type":"paragraph","content":[{"type":"text","text":"4"}]}]}]},{"type":"tableRow","content":[{"type":"tableCell","attrs":{"background":"white"},"content":[{"type":"paragraph","content":[{"type":"text","text":"LIDs Shared"}]}]},{"type":"tableCell","attrs":{"background":"white"},"content":[{"type":"paragraph","content":[{"type":"text","text":"84"}]}]},{"type":"tableCell","attrs":{"background":"white"},"content":[{"type":"paragraph","content":[{"type":"text","text":"17"}]}]}]},{"type":"tableRow","content":[{"type":"tableCell","attrs":{"background":"white"},"content":[{"type":"paragraph","content":[{"type":"text","text":"LIDs Stuck in the System"}]}]},{"type":"tableCell","attrs":{"background":"white"},"content":[{"type":"paragraph","content":[{"type":"text","text":"0"}]}]},{"type":"tableCell","attrs":{"background":"white"},"content":[{"type":"paragraph","content":[{"type":"text","text":"0"}]}]}]}]} {adf} Regards, Team Netscribes | S10: =IF(OR(G10="",H10=""),"",ROUND(H10-G10,2)) -> 11.79
A11: UCW-30534 | B11: Support Required for Bulk Category-wise Listing Upload - Rajnandini | C11: CLOSED | D11: Medium | E11: Chirag Dubal | F11: Shraddha Dighe | G11: 46143.969 | H11: 46150.599 | I11: 342 | J11: E2E | K11: E2E | L11: Apparel | M11: 332 | N11: 55 | O11: 57 | P11: Rajnandini | Q11: Mall | R11: PFA the Post Upload Sheet & Summary. [^Post Upload Status_30534.xlsx] [^Summary.zip] ;[^UCW-30534_LID.xlsx] Hi [@Jainam Overseas Pvt Ltd|mailto:info@rajnandinifashion.com], Please find attached the sheet, where 55 options have been listed. Kindly update the price and inventory, and share the summary once completed. {adf:display=block} {"type":"table","attrs":{"isNumberColumnEnabled":false,"layout":"center","localId":"f362f5e3-cd32-4f18-8082-fed7cdad9924"},"content":[{"type":"tableRow","content":[{"type":"tableCell","attrs":{"background":"#44b3e1"},"content":[{"type":"paragraph","content":[{"type":"text","text":"Ticket ID","marks":[{"type":"strong"}]}]}]},{"type":"tableCell","attrs":{"colspan":2,"background":"#44b3e1"},"content":[{"type":"paragraph","content":[{"type":"text","text":"UCW-30534","marks":[{"type":"strong"}]}]}]}]},{"type":"tableRow","content":[{"type":"tableCell","attrs":{"background":"#44b3e1"},"content":[{"type":"paragraph","content":[{"type":"text","text":"Brand Name","marks":[{"type":"strong"}]}]}]},{"type":"tableCell","attrs":{"colspan":2,"background":"#44b3e1"},"content":[{"type":"paragraph","content":[{"type":"text","text":"Rajnandini","marks":[{"type":"strong"}]}]}]}]},{"type":"tableRow","content":[{"type":"tableCell","attrs":{"background":"#44b3e1"},"content":[{"type":"paragraph","content":[{"type":"text","text":"Platform","marks":[{"type":"strong"}]}]}]},{"type":"tableCell","attrs":{"colspan":2,"background":"#44b3e1"},"content":[{"type":"paragraph","content":[{"type":"text","text":"Mall","marks":[{"type":"strong"}]}]}]}]},{"type":"tableRow","content":[{"type":"tableCell","attrs":{"background":"#ace5fe"},"content":[{"type":"paragraph","content":[{"type":"text","text":"Particulars","marks":[{"type":"strong"}]}]}]},{"type":"tableCell","attrs":{"background":"#ace5fe"},"content":[{"type":"paragraph","content":[{"type":"text","text":"SKU Count","marks":[{"type":"strong"}]}]}]},{"type":"tableCell","attrs":{"background":"#ace5fe"},"content":[{"type":"paragraph","content":[{"type":"text","text":"Option Count","marks":[{"type":"strong"}]}]}]}]},{"type":"tableRow","content":[{"type":"tableCell","attrs":{"background":"white"},"content":[{"type":"paragraph","content":[{"type":"text","text":"Received"}]}]},{"type":"tableCell","attrs":{"background":"white"},"content":[{"type":"paragraph","content":[{"type":"text","text":"342"}]}]},{"type":"tableCell","attrs":{"background":"white"},"content":[{"type":"paragraph","content":[{"type":"text","text":"57"}]}]}]},{"type":"tableRow","content":[{"type":"tableCell","attrs":{"background":"white"},"content":[{"type":"paragraph","content":[{"type":"text","text":"Uploaded"}]}]},{"type":"tableCell","attrs":{"background":"white"},"content":[{"type":"paragraph","content":[{"type":"text","text":"332"}]}]},{"type":"tableCell","attrs":{"background":"white"},"content":[{"type":"paragraph","content":[{"type":"text","text":"55"}]}]}]},{"type":"tableRow","content":[{"type":"tableCell","attrs":{"background":"white"},"content":[{"type":"paragraph","content":[{"type":"text","text":"Not Uploaded"}]}]},{"type":"tableCell","attrs":{"background":"white"},"content":[{"type":"paragraph","content":[{"type":"text","text":"10"}]}]},{"type":"tableCell","attrs":{"background":"white"},"content":[{"type":"paragraph","content":[{"type":"text","text":"2"}]}]}]},{"type":"tableRow","content":[{"type":"tableCell","attrs":{"background":"white"},"content":[{"type":"paragraph","content":[{"type":"text","text":"LIDs Shared"}]}]},{"type":"tableCell","attrs":{"background":"white"},"content":[{"type":"paragraph","content":[{"type":"text","text":"332"}]}]},{"type":"tableCell","attrs":{"background":"white"},"content":[{"type":"paragraph","content":[{"type":"text","text":"55"}]}]}]},{"type":"tableRow","content":[{"type":"tableCell","attrs":{"background":"white"},"content":[{"type":"paragraph","content":[{"type":"text","text":"LIDs Stuck in the System"}]}]},{"type":"tableCell","attrs":{"background":"white"},"content":[{"type":"paragraph","content":[{"type":"text","text":"0"}]}]},{"type":"tableCell","attrs":{"background":"white"},"content":[{"type":"paragraph","content":[{"type":"text","text":"0"}]}]}]}]} {adf} Regards, Team Netscribes | S11: =IF(OR(G11="",H11=""),"",ROUND(H11-G11,2)) -> 6.63
A12: UCW-30535 | B12: Globus Women's Wear Apparels - 22 Styles - Batch 132 (Brand - Globus Stores Pvt Ltd) (Ethnic Wear) (27.04.2026) | C12: CLOSED | D12: Medium | E12: Chirag Dubal | F12: Shraddha Dighe | G12: 46143.973 | H12: 46155.738 | I12: 88 | J12: E2E | K12: E2E | L12: Apparel | M12: 88 | N12: 22 | O12: 22 | P12: Globus | Q12: Mall | R12: PFA the Post Upload Sheet & Summary. [^Summary.zip] [^Post Upload Status_UCW-30535.xlsx] ;[^UCW-30535_LID.xlsx] Hi [@Ganesh Rolekar|mailto:ganeshr@globusmail.com], Please find attached the sheet, where 22 options have been listed. Kindly update the price and inventory, and share the summary once completed. {adf:display=block} {"type":"table","attrs":{"isNumberColumnEnabled":false,"layout":"center","localId":"a34b7cf4-694c-4b22-8adc-831f4001456a"},"content":[{"type":"tableRow","content":[{"type":"tableCell","attrs":{"background":"#44b3e1"},"content":[{"type":"paragraph","content":[{"type":"text","text":"Ticket ID","marks":[{"type":"strong"}]}]}]},{"type":"tableCell","attrs":{"colspan":2,"background":"#44b3e1"},"content":[{"type":"paragraph","content":[{"type":"text","text":"UCW-30535","marks":[{"type":"strong"}]}]}]}]},{"type":"tableRow","content":[{"type":"tableCell","attrs":{"background":"#44b3e1"},"content":[{"type":"paragraph","content":[{"type":"text","text":"Brand Name","marks":[{"type":"strong"}]}]}]},{"type":"tableCell","attrs":{"colspan":2,"background":"#44b3e1"},"content":[{"type":"paragraph","content":[{"type":"text","text":"Globus ","marks":[{"type":"strong"}]}]}]}]},{"type":"tableRow","content":[{"type":"tableCell","attrs":{"background":"#44b3e1"},"content":[{"type":"paragraph","content":[{"type":"text","text":"Platform","marks":[{"type":"strong"}]}]}]},{"type":"tableCell","attrs":{"colspan":2,"background":"#44b3e1"},"content":[{"type":"paragraph","content":[{"type":"text","text":"Mall","marks":[{"type":"strong"}]}]}]}]},{"type":"tableRow","content":[{"type":"tableCell","attrs":{"background":"#ace5fe"},"content":[{"type":"paragraph","content":[{"type":"text","text":"Particulars","marks":[{"type":"strong"}]}]}]},{"type":"tableCell","attrs":{"background":"#ace5fe"},"content":[{"type":"paragraph","content":[{"type":"text","text":"SKU Count","marks":[{"type":"strong"}]}]}]},{"type":"tableCell","attrs":{"background":"#ace5fe"},"content":[{"type":"paragraph","content":[{"type":"text","text":"Option Count","marks":[{"type":"strong"}]}]}]}]},{"type":"tableRow","content":[{"type":"tableCell","attrs":{"background":"white"},"content":[{"type":"paragraph","content":[{"type":"text","text":"Received"}]}]},{"type":"tableCell","attrs":{"background":"white"},"content":[{"type":"paragraph","content":[{"type":"text","text":"88"}]}]},{"type":"tableCell","attrs":{"background":"white"},"content":[{"type":"paragraph","content":[{"type":"text","text":"22"}]}]}]},{"type":"tableRow","content":[{"type":"tableCell","attrs":{"background":"white"},"content":[{"type":"paragraph","content":[{"type":"text","text":"Uploaded"}]}]},{"type":"tableCell","attrs":{"background":"white"},"content":[{"type":"paragraph","content":[{"type":"text","text":"88"}]}]},{"type":"tableCell","attrs":{"background":"white"},"content":[{"type":"paragraph","content":[{"type":"text","text":"22"}]}]}]},{"type":"tableRow","content":[{"type":"tableCell","attrs":{"background":"white"},"content":[{"type":"paragraph","content":[{"type":"text","text":"Not Uploaded"}]}]},{"type":"tableCell","attrs":{"background":"white"},"content":[{"type":"paragraph","content":[{"type":"text","text":"0"}]}]},{"type":"tableCell","attrs":{"background":"white"},"content":[{"type":"paragraph","content":[{"type":"text","text":"0"}]}]}]},{"type":"tableRow","content":[{"type":"tableCell","attrs":{"background":"white"},"content":[{"type":"paragraph","content":[{"type":"text","text":"LIDs Shared"}]}]},{"type":"tableCell","attrs":{"background":"white"},"content":[{"type":"paragraph","content":[{"type":"text","text":"88"}]}]},{"type":"tableCell","attrs":{"background":"white"},"content":[{"type":"paragraph","content":[{"type":"text","text":"22"}]}]}]},{"type":"tableRow","content":[{"type":"tableCell","attrs":{"background":"white"},"content":[{"type":"paragraph","content":[{"type":"text","text":"LIDs Stuck in the System"}]}]},{"type":"tableCell","attrs":{"background":"white"},"content":[{"type":"paragraph","content":[{"type":"text","text":"0"}]}]},{"type":"tableCell","attrs":{"background":"white"},"content":[{"type":"paragraph","content":[{"type":"text","text":"0"}]}]}]}]} {adf} Regards, Team Netscribes | S12: =IF(OR(G12="",H12=""),"",ROUND(H12-G12,2)) -> 11.76
A13: UCW-30536 | B13: K18 Hair Oil 10ml New Listing | C13: CLOSED | D13: Medium | E13: Chirag Dubal | F13: Shraddha Dighe | G13: 46143.981 | H13: 46149.669 | I13: 1 | J13: E2E | K13: E2E | L13: Beauty & Grooming | M13: 1 | N13: 1 | O13: 1 | P13: K18 | Q13: Mall;Luxury | R13: [^UCW-30536 Post Upload Status_V.2 (1).xlsx] [^Summary.zip] ;[^UCW-30536_LID.xlsx] Hi [@Shobhakant|mailto:Shobhakant@mkexim.co.in], Please find attached the sheet, where 1 options have been listed. Kindly update the price and inventory, and share the summary once completed. {adf:display=block} {"type":"table","attrs":{"isNumberColumnEnabled":false,"layout":"center","localId":"fb22e979-1634-4ff0-8d9b-fe24054db616"},"content":[{"type":"tableRow","content":[{"type":"tableCell","attrs":{"background":"#44b3e1"},"content":[{"type":"paragraph","content":[{"type":"text","text":"Ticket ID","marks":[{"type":"strong"}]}]}]},{"type":"tableCell","attrs":{"colspan":2,"background":"#44b3e1"},"content":[{"type":"paragraph","content":[{"type":"text","text":"UCW-30536","marks":[{"type":"strong"}]}]}]}]},{"type":"tableRow","content":[{"type":"tableCell","attrs":{"background":"#44b3e1"},"content":[{"type":"paragraph","content":[{"type":"text","text":"Brand Name","marks":[{"type":"strong"}]}]}]},{"type":"tableCell","attrs":{"colspan":2,"background":"#44b3e1"},"content":[{"type":"paragraph","content":[{"type":"text","text":"K18","marks":[{"type":"strong"}]}]}]}]},{"type":"tableRow","content":[{"type":"tableCell","attrs":{"background":"#44b3e1"},"content":[{"type":"paragraph","content":[{"type":"text","text":"Platform","marks":[{"type":"strong"}]}]}]},{"type":"tableCell","attrs":{"colspan":2,"background":"#44b3e1"},"content":[{"type":"paragraph","content":[{"type":"text","text":"Mall, Luxury","marks":[{"type":"strong"}]}]}]}]},{"type":"tableRow","content":[{"type":"tableCell","attrs":{"background":"#ace5fe"},"content":[{"type":"paragraph","content":[{"type":"text","text":"Particulars","marks":[{"type":"strong"}]}]}]},{"type":"tableCell","attrs":{"background":"#ace5fe"},"content":[{"type":"paragraph","content":[{"type":"text","text":"SKU Count","marks":[{"type":"strong"}]}]}]},{"type":"tableCell","attrs":{"background":"#ace5fe"},"content":[{"type":"paragraph","content":[{"type":"text","text":"Option Count","marks":[{"type":"strong"}]}]}]}]},{"type":"tableRow","content":[{"type":"tableCell","attrs":{"background":"white"},"content":[{"type":"paragraph","content":[{"type":"text","text":"Received"}]}]},{"type":"tableCell","attrs":{"background":"white"},"content":[{"type":"paragraph","content":[{"type":"text","text":"1"}]}]},{"type":"tableCell","attrs":{"background":"white"},"content":[{"type":"paragraph","content":[{"type":"text","text":"1"}]}]}]},{"type":"tableRow","content":[{"type":"tableCell","attrs":{"background":"white"},"content":[{"type":"paragraph","content":[{"type":"text","text":"Uploaded"}]}]},{"type":"tableCell","attrs":{"background":"white"},"content":[{"type":"paragraph","content":[{"type":"text","text":"1"}]}]},{"type":"tableCell","attrs":{"background":"white"},"content":[{"type":"paragraph","content":[{"type":"text","text":"1"}]}]}]},{"type":"tableRow","content":[{"type":"tableCell","attrs":{"background":"white"},"content":[{"type":"paragraph","content":[{"type":"text","text":"Not Uploaded"}]}]},{"type":"tableCell","attrs":{"background":"white"},"content":[{"type":"paragraph","content":[{"type":"text","text":"0"}]}]},{"type":"tableCell","attrs":{"background":"white"},"content":[{"type":"paragraph","content":[{"type":"text","text":"0"}]}]}]},{"type":"tableRow","content":[{"type":"tableCell","attrs":{"background":"white"},"content":[{"type":"paragraph","content":[{"type":"text","text":"LIDs Shared"}]}]},{"type":"tableCell","attrs":{"background":"white"},"content":[{"type":"paragraph","content":[{"type":"text","text":"1"}]}]},{"type":"tableCell","attrs":{"background":"white"},"content":[{"type":"paragraph","content":[{"type":"text","text":"1"}]}]}]},{"type":"tableRow","content":[{"type":"tableCell","attrs":{"background":"white"},"content":[{"type":"paragraph","content":[{"type":"text","text":"LIDs Stuck in the System"}]}]},{"type":"tableCell","attrs":{"background":"white"},"content":[{"type":"paragraph","content":[{"type":"text","text":"0"}]}]},{"type":"tableCell","attrs":{"background":"white"},"content":[{"type":"paragraph","content":[{"type":"text","text":"0"}]}]}]}]} {adf} Regards, Team Netscribes | S13: =IF(OR(G13="",H13=""),"",ROUND(H13-G13,2)) -> 5.69
A14: UCW-30537 | B14: ENRICH_Image Update: Charcoal Peel Off Mask // Tatacliq | C14: CLOSED | D14: Medium | E14: Chirag Dubal | F14: Shraddha Dighe | G14: 46143.983 | H14: 46145.745 | I14: 1 | J14: Ad-hoc | K14: Retrigger Image | L14: Beauty & Grooming | M14: 1 | N14: 1 | O14: 1 | P14: Love Earth | Q14: Mall | S14: =IF(OR(G14="",H14=""),"",ROUND(H14-G14,2)) -> 1.76
A15: UCW-30543 | B15: Enrichment_Tata Cliq - Image Update - Banderas (29-04-2026) | C15: CLOSED | D15: Medium | E15: Chirag Dubal | F15: Reagan D’souza | G15: 46144.603 | H15: 46161.7 | I15: 2 | J15: Ad-hoc | K15: Retrigger Image | L15: Accessories | M15: 2 | N15: 2 | O15: 2 | P15: Banderas | Q15: Mall | R15: [^Status Of UCW-30543.xlsx] [^Summary.zip] We have updated the images and also attached the summary file. Once the images are successfully reflected we will let you know | S15: =IF(OR(G15="",H15=""),"",ROUND(H15-G15,2)) -> 17.1
A16: UCW-30544 | B16: Error_Hoversoul Batch -9_NC | C16: CLOSED | D16: Medium | E16: Chirag Dubal | F16: Reagan D’souza | G16: 46144.61 | H16: 46155.662 | I16: 10 | J16: Ad-hoc | K16: PDP/PLP QC | L16: Apparel | M16: 10 | N16: 10 | O16: 10 | P16: Hoversoul | Q16: Mall | S16: =IF(OR(G16="",H16=""),"",ROUND(H16-G16,2)) -> 11.05
A17: UCW-30550 | B17: Skechers Add now catalogue dated 15th April 2026 | C17: CLOSED | D17: Medium | E17: Chirag Dubal | F17: netscribes | G17: 46144.631 | H17: 46144.639 | I17: 0 | J17: E2E | K17: E2E | L17: Footwear | M17: 0 | N17: 0 | O17: 0 | P17: Sketchers | Q17: Mall | S17: =IF(OR(G17="",H17=""),"",ROUND(H17-G17,2)) -> 0.01 | U17: No task was assigned for this ticket
A18: UCW-30555 | B18: Error_Andon Cord | Thrice Wrong Product Delivered | Allen Cooper | C18: CLOSED | D18: Medium | E18: Chirag Dubal | F18: Reagan D’souza | G18: 46146.476 | H18: 46158.538 | I18: 5 | J18: Ad-hoc | K18: Detractor Cases | L18: Apparel | M18: 5 | N18: 5 | O18: 5 | P18: Allen Cooper | Q18: Mall | S18: =IF(OR(G18="",H18=""),"",ROUND(H18-G18,2)) -> 12.06
A19: UCW-30557 | B19: Tata Cliq Luxury - New listing - Fragrance MDP (GWP) 02-05-2026 | C19: CLOSED | D19: Medium | E19: Chirag Dubal | F19: Shraddha Dighe | G19: 46146.481 | H19: 46163.626 | I19: 21 | J19: E2E | K19: GWP | L19: Beauty & Grooming | M19: 18 | N19: 18 | O19: 21 | P19: Multiple | Q19: Luxury | R19: [^UCW-30557 Post Upload Status_V.2 (1).xlsx] [^Summary.zip] ; We are pleased to inform you that the listing IDs have been generated successfully. Please find the attached file for your reference, along with the summary table below. You may now proceed with price and inventory pushing from your end. {adf:display=block} {"type":"table","attrs":{"isNumberColumnEnabled":false,"layout":"center","localId":"8589c2e4-7522-4ef0-8968-f2343ea79e9d"},"content":[{"type":"tableRow","content":[{"type":"tableCell","attrs":{"background":"#44b3e1"},"content":[{"type":"paragraph","content":[{"type":"text","text":"Ticket ID","marks":[{"type":"strong"}]}]}]},{"type":"tableCell","attrs":{"colspan":2,"background":"#44b3e1"},"content":[{"type":"paragraph","content":[{"type":"text","text":"UCW-30557","marks":[{"type":"strong"}]}]}]}]},{"type":"tableRow","content":[{"type":"tableCell","attrs":{"background":"#44b3e1"},"content":[{"type":"paragraph","content":[{"type":"text","text":"Brand Name","marks":[{"type":"strong"}]}]}]},{"type":"tableCell","attrs":{"colspan":2,"background":"#44b3e1"},"content":[{"type":"paragraph","content":[{"type":"text","text":"Multiple","marks":[{"type":"strong"}]}]}]}]},{"type":"tableRow","content":[{"type":"tableCell","attrs":{"background":"#ace5fe"},"content":[{"type":"paragraph","content":[{"type":"text","text":"Platform","marks":[{"type":"strong"}]}]}]},{"type":"tableCell","attrs":{"colspan":2,"background":"#ace5fe"},"content":[{"type":"paragraph","content":[{"type":"text","text":"LUX","marks":[{"type":"strong"}]}]}]}]},{"type":"tableRow","content":[{"type":"tableCell","attrs":{"background":"#ace5fe"},"content":[{"type":"paragraph","content":[{"type":"text","text":"Particulars","marks":[{"type":"strong"}]}]}]},{"type":"tableCell","attrs":{"background":"#ace5fe"},"content":[{"type":"paragraph","content":[{"type":"text","text":"SKU Count","marks":[{"type":"strong"}]}]}]},{"type":"tableCell","attrs":{"background":"#ace5fe"},"content":[{"type":"paragraph","content":[{"type":"text","text":"Option Count","marks":[{"type":"strong"}]}]}]}]},{"type":"tableRow","content":[{"type":"tableCell","attrs":{"background":"white"},"content":[{"type":"paragraph","content":[{"type":"text","text":"Received"}]}]},{"type":"tableCell","attrs":{},"content":[{"type":"paragraph","content":[{"type":"text","text":"21"}]}]},{"type":"tableCell","attrs":{},"content":[{"type":"paragraph","content":[{"type":"text","text":"21"}]}]}]},{"type":"tableRow","content":[{"type":"tableCell","attrs":{"background":"white"},"content":[{"type":"paragraph","content":[{"type":"text","text":"Uploaded"}]}]},{"type":"tableCell","attrs":{},"content":[{"type":"paragraph","content":[{"type":"text","text":"18"}]}]},{"type":"tableCell","attrs":{},"content":[{"type":"paragraph","content":[{"type":"text","text":"18"}]}]}]},{"type":"tableRow","content":[{"type":"tableCell","attrs":{"background":"white"},"content":[{"type":"paragraph","content":[{"type":"text","text":"SKUs not uploaded"}]}]},{"type":"tableCell","attrs":{},"content":[{"type":"paragraph","content":[{"type":"text","text":"0"}]}]},{"type":"tableCell","attrs":{},"content":[{"type":"paragraph","content":[{"type":"text","text":"0"}]}]}]},{"type":"tableRow","content":[{"type":"tableCell","attrs":{"background":"white"},"content":[{"type":"paragraph","content":[{"type":"text","text":"Already Listed"}]}]},{"type":"tableCell","attrs":{},"content":[{"type":"paragraph","content":[{"type":"text","text":"3"}]}]},{"type":"tableCell","attrs":{},"content":[{"type":"paragraph","content":[{"type":"text","text":"3"}]}]}]},{"type":"tableRow","content":[{"type":"tableCell","attrs":{"background":"white"},"content":[{"type":"paragraph","content":[{"type":"text","text":"LIDs Shared"}]}]},{"type":"tableCell","attrs":{},"content":[{"type":"paragraph","content":[{"type":"text","text":"18"}]}]},{"type":"tableCell","attrs":{},"content":[{"type":"paragraph","content":[{"type":"text","text":"18"}]}]}]},{"type":"tableRow","content":[{"type":"tableCell","attrs":{"background":"white"},"content":[{"type":"paragraph","content":[{"type":"text","text":"LIDs Stuck in the System"}]}]},{"type":"tableCell","attrs":{},"content":[{"type":"paragraph","content":[{"type":"text","text":"0"}]}]},{"type":"tableCell","attrs":{},"content":[{"type":"paragraph","content":[{"type":"text","text":"0"}]}]}]}]} {adf} With this, we are closing this request from our end. Thank you for your patience, support, and cooperation throughout the process. Your brand is important to us, and we look forward to assisting you again.[^UCW-30557 Post Upload Status_V.2 (1) (54f2d411-e2be-450c-a74f-87f6357ee4dd).xlsx] | S19: =IF(OR(G19="",H19=""),"",ROUND(H19-G19,2)) -> 17.15 | U19: uploaded on 12th and closed on 15th after validating
A20: UCW-30574 | B20: New Listing | CareVeda x TataCliq | 15th April 2026 | C20: CLOSED | D20: Medium | E20: Chirag Dubal | F20: Shraddha Dighe | G20: 46146.534 | H20: 46163.626 | I20: 38 | J20: E2E | K20: E2E | L20: Beauty & Grooming | M20: 38 | N20: 38 | O20: 38 | P20: CareVeda | Q20: Mall | R20: [^UCW-30574 Post Upload Status_V.2 (1).xlsx] [^Summary.zip] ; We are pleased to inform you that the listing IDs have been generated successfully. Please find the attached file for your reference, along with the summary table below. You may now proceed with price and inventory pushing from your end. {adf:display=block} {"type":"table","attrs":{"isNumberColumnEnabled":false,"layout":"center","localId":"a1cb6d57-383a-495c-b682-c7905b8f2490"},"content":[{"type":"tableRow","content":[{"type":"tableCell","attrs":{"background":"#44b3e1"},"content":[{"type":"paragraph","content":[{"type":"text","text":"Ticket ID","marks":[{"type":"strong"}]}]}]},{"type":"tableCell","attrs":{"colspan":2,"background":"#44b3e1"},"content":[{"type":"paragraph","content":[{"type":"text","text":"UCW-30574","marks":[{"type":"strong"}]}]}]}]},{"type":"tableRow","content":[{"type":"tableCell","attrs":{"background":"#44b3e1"},"content":[{"type":"paragraph","content":[{"type":"text","text":"Brand Name","marks":[{"type":"strong"}]}]}]},{"type":"tableCell","attrs":{"colspan":2,"background":"#44b3e1"},"content":[{"type":"paragraph","content":[{"type":"text","text":"CareVeda","marks":[{"type":"strong"}]}]}]}]},{"type":"tableRow","content":[{"type":"tableCell","attrs":{"background":"#ace5fe"},"content":[{"type":"paragraph","content":[{"type":"text","text":"Platform","marks":[{"type":"strong"}]}]}]},{"type":"tableCell","attrs":{"colspan":2,"background":"#ace5fe"},"content":[{"type":"paragraph","content":[{"type":"text","text":"Mall","marks":[{"type":"strong"}]}]}]}]},{"type":"tableRow","content":[{"type":"tableCell","attrs":{"background":"#ace5fe"},"content":[{"type":"paragraph","content":[{"type":"text","text":"Particulars","marks":[{"type":"strong"}]}]}]},{"type":"tableCell","attrs":{"background":"#ace5fe"},"content":[{"type":"paragraph","content":[{"type":"text","text":"SKU Count","marks":[{"type":"strong"}]}]}]},{"type":"tableCell","attrs":{"background":"#ace5fe"},"content":[{"type":"paragraph","content":[{"type":"text","text":"Option Count","marks":[{"type":"strong"}]}]}]}]},{"type":"tableRow","content":[{"type":"tableCell","attrs":{"background":"white"},"content":[{"type":"paragraph","content":[{"type":"text","text":"Received"}]}]},{"type":"tableCell","attrs":{},"content":[{"type":"paragraph","content":[{"type":"text","text":"38"}]}]},{"type":"tableCell","attrs":{},"content":[{"type":"paragraph","content":[{"type":"text","text":"38"}]}]}]},{"type":"tableRow","content":[{"type":"tableCell","attrs":{"background":"white"},"content":[{"type":"paragraph","content":[{"type":"text","text":"Uploaded"}]}]},{"type":"tableCell","attrs":{},"content":[{"type":"paragraph","content":[{"type":"text","text":"38"}]}]},{"type":"tableCell","attrs":{},"content":[{"type":"paragraph","content":[{"type":"text","text":"38"}]}]}]},{"type":"tableRow","content":[{"type":"tableCell","attrs":{"background":"white"},"content":[{"type":"paragraph","content":[{"type":"text","text":"SKUs not uploaded"}]}]},{"type":"tableCell","attrs":{},"content":[{"type":"paragraph","content":[{"type":"text","text":"-"}]}]},{"type":"tableCell","attrs":{},"content":[{"type":"paragraph","content":[{"type":"text","text":"-"}]}]}]},{"type":"tableRow","content":[{"type":"tableCell","attrs":{"background":"white"},"content":[{"type":"paragraph","content":[{"type":"text","text":"Already Listed"}]}]},{"type":"tableCell","attrs":{},"content":[{"type":"paragraph","content":[{"type":"text","text":"-"}]}]},{"type":"tableCell","attrs":{},"content":[{"type":"paragraph","content":[{"type":"text","text":"-"}]}]}]},{"type":"tableRow","content":[{"type":"tableCell","attrs":{"background":"white"},"content":[{"type":"paragraph","content":[{"type":"text","text":"LIDs Shared"}]}]},{"type":"tableCell","attrs":{},"content":[{"type":"paragraph","content":[{"type":"text","text":"38"}]}]},{"type":"tableCell","attrs":{},"content":[{"type":"paragraph","content":[{"type":"text","text":"38"}]}]}]},{"type":"tableRow","content":[{"type":"tableCell","attrs":{"background":"white"},"content":[{"type":"paragraph","content":[{"type":"text","text":"LIDs Stuck in the System"}]}]},{"type":"tableCell","attrs":{},"content":[{"type":"paragraph","content":[{"type":"text","text":"-"}]}]},{"type":"tableCell","attrs":{},"content":[{"type":"paragraph","content":[{"type":"text","text":"-"}]}]}]}]} {adf} With this, we are closing this request from our end. Thank you for your patience, support, and cooperation throughout the process. Your brand is important to us, and we look forward to assisting you again.[^UCW-30574 Post Upload Status_V.2 (1) (110ee1c8-1f29-4577-99d2-5ddc1d8e37bb).xlsx] | S20: =IF(OR(G20="",H20=""),"",ROUND(H20-G20,2)) -> 17.09 | U20: uploaded on 12th and closed on 15th after validating
